Workbook

Sheet Question Bank
A1: ID | B1: Lesson | C1: Lesson title | D1: section_tag | E1: Question text | F1: Answer A | G1: Answer B | H1: Answer C | I1: Answer D | J1: correct_index (0-3) | K1: Correct answer (auto) | L1: Explanation | M1: Status | N1: Reviewer notes | O1: Grounded in (course section)
A2: L1-01 | B2: 1 | C2: Introduction to AI in Legal Practice | D2: L1:rule-53-duty | E2: Which statement best describes an attorney's duty regarding AI tools used by their staff? | F2: Attorneys have partial duty to supervise AI tools because they are not people. Only the software company is responsible | G2: Attorneys must make reasonable efforts to ensure staff AI use is compatible with professional obligations | H2: Supervision duties apply only to licensed paralegals, not other staff | I2: AI tools are exempt from supervision requirements under all state bar rules | J2: 1 | K2: =IF(OR($J2="",NOT(ISNUMBER($J2)),$J2<0,$J2>3,COUNTA($F2:$I2)<4),"",INDEX($F2:$I2,$J2+1)) | L2: Attorneys should make reasonable efforts to ensure the conduct of non-lawyer assistants, including their use of AI tools, is compatible with the lawyer's professional obligations. | M2: Ready for Katy | N2: Existing seed question. Tagged PLACEHOLDER in section_tag only: the text itself is real. Review for legal accuracy, then retag. | O2: Lesson 1: ABA Model Rule 5.3 / Why It Matters for Everyone
A3: L1-02 | B3: 1 | C3: Introduction to AI in Legal Practice | D3: L1:two-pillars | E3: A staff member uploads a confidential client file to a public AI tool, and the summary it returns contains a case citation that does not exist. Which of the firm's two core compliance concerns does this single incident raise? | F3: Confidentiality only, because the upload is what exposed client data, and a citation nobody relied on causes no harm | G3: Accuracy only, because nobody outside the firm has read the file and the vendor's terms forbid disclosure | H3: Both confidentiality and accuracy, because the upload and the fabricated citation are separate failures | I3: Neither yet, because the summary has not been used in client work and can still be discarded before anyone relies on it | J3: 2 | K3: =IF(OR($J3="",NOT(ISNUMBER($J3)),$J3<0,$J3>3,COUNTA($F3:$I3)<4),"",INDEX($F3:$I3,$J3+1)) | L3: Lesson 1 treats confidentiality and accuracy as two distinct concerns needing separate attention. Uploading the file is a confidentiality breach on its own, and the fabricated citation is an accuracy failure on its own. Each of the other options is true as far as it goes but stops a step short: the upload really is the exposure, nobody may have read it yet, and the summary has not yet been used. None of that changes the fact that two separate failures have already happened. | M3: Ready for Katy | N3: DISTRACTORS LENGTHENED 08-18 so answer length stops signalling the key. Correct answer untouched. Drafted from course text. Distractors are each true about something and wrong only in what they conclude. | O3: Lesson 1: The Two Pillars of AI Compliance
A4: L1-03 | B4: 1 | C4: Introduction to AI in Legal Practice | D4: L1:automation-config | E4: A firm's intake automation moves client data between systems without anyone pasting anything into a chat window. What determines whether it actually protects confidentiality? | F4: Whether it was configured to use secure channels and approved by the firm | G4: That it is an automation rather than a chatbox, since automations are built for secure processing | H4: Whether the data stays within the United States | I4: Whether staff have been trained on how to run it | J4: 0 | K4: =IF(OR($J4="",NOT(ISNUMBER($J4)),$J4<0,$J4>3,COUNTA($F4:$I4)<4),"",INDEX($F4:$I4,$J4+1)) | L4: Lesson 1 warns that automations can pose the same confidentiality risks as chatboxes when they are not set up correctly. Automations genuinely are built for secure, repeatable processes, data location is one of Lesson 5's four vendor criteria, and training is one of Lesson 4's three approval requirements. Each is a real factor. But the protection comes from the configuration and the firm's approval, not from the category the tool falls into. | M4: Ready for Katy | N4: Drafted from course text. Distractors are each true about something and wrong only in what they conclude. | O4: Lesson 1: AI Automations / Lesson 4: What Makes a Workflow Approved
A5: L1-04 | B5: 1 | C5: Introduction to AI in Legal Practice | D5: L1:risk-categories | E5: A legal assistant asks an AI tool how a particular judge is likely to rule and repeats the answer to the client. Under the three compliance risks the course names, this is most directly an example of: | F5: Unintentional disclosure of confidential information | G5: Reliance on inaccurate or hallucinated output | H5: A firm policy matter rather than an ethics matter | I5: Improper or unsupervised use of an AI tool | J5: 3 | K5: =IF(OR($J5="",NOT(ISNUMBER($J5)),$J5<0,$J5>3,COUNTA($F5:$I5)<4),"",INDEX($F5:$I5,$J5+1)) | L5: Lesson 1's third risk category is improper or unsupervised use, and its two named examples are relying on AI for legal advice without oversight and using AI for case predictions, which is exactly this. The other risks are genuinely present too: describing the matter may disclose client facts, and the prediction itself may be invented. Firm policy does also cover it. The question asks which fits most directly, and the course names this scenario by name. | M5: Ready for Katy | N5: Two other options are defensible on their own terms. Confirm 'most directly' is a fair framing, or tighten the stem. | O5: Lesson 1: Overview of AI Compliance Risks in Law Firms
A6: L1-05 | B6: 1 | C6: Introduction to AI in Legal Practice | D6: L1:risk-chain | E6: The course traces how compliance risk develops: a tool is chosen, sensitive information is entered, output is generated, then the output is used in client work without review. Once information has already been entered into an unapproved tool, what can still be prevented? | F6: The inaccurate output reaching the client, if the draft is verified before use | G6: Nothing, the breach is complete and the remaining steps no longer matter | H6: The confidentiality exposure, if the conversation is deleted promptly | I6: Both the exposure and the inaccuracy, if a supervising attorney is notified | J6: 0 | K6: =IF(OR($J6="",NOT(ISNUMBER($J6)),$J6<0,$J6>3,COUNTA($F6:$I6)<4),"",INDEX($F6:$I6,$J6+1)) | L6: Lesson 2 explains that prompts may be retained, reviewed, or used to train future models, so the confidentiality exposure happens at the moment of entry and deleting the conversation afterward does not reach copies already held. What is still preventable is the second, separate failure: verification before the output reaches client work. Notifying the supervising attorney is genuinely required under Lesson 3, and it is the right next step, but it governs the response to the breach rather than reversing it. | M6: Ready for Katy | N6: Drafted from course text. Distractors are each true about something and wrong only in what they conclude. | O6: Lesson 1: How compliance risks can develop / Lesson 2: How AI Chatboxes Put Confidentiality at Risk
A7: L1-06 | B7: 1 | C7: Introduction to AI in Legal Practice | D7: L1:staff-scope | E7: Which best describes a non-attorney staff member's own obligation? | F7: None directly, since Rule 5.3 places the supervisory duty on the attorney | G7: To independently assess whether each AI tool meets the firm's security standards | H7: To review all AI output for legal accuracy before it reaches the attorney | I7: To follow firm AI policy, avoid unauthorized legal advice, and flag compliance risks | J7: 3 | K7: =IF(OR($J7="",NOT(ISNUMBER($J7)),$J7<0,$J7>3,COUNTA($F7:$I7)<4),"",INDEX($F7:$I7,$J7+1)) | L7: Rule 5.3 does place the supervisory duty on the attorney, which is what makes the answer denying any direct obligation half right. But Lesson 1 states the rule means support staff, not only lawyers, carry a direct responsibility to understand and uphold compliance. Lesson 4 draws the boundary on the other side: staff are explicitly not expected to determine the technical details of compliance. Lesson 3 gives attorneys, not staff, final responsibility for legal accuracy, though staff do review drafts for obvious errors. | M7: Ready for Katy | N7: Drafted from course text. Distractors are each true about something and wrong only in what they conclude. | O7: Lesson 1: Roles and Responsibilities in the Law Firm
A8: L1-07 | B8: 1 | C8: Introduction to AI in Legal Practice | D8: L1:tool-selection | E8: A firm wants to summarize attorney notes into client-file records, the same way every time. Based on the two tool categories the course describes, which is appropriate and why? | F8: A chatbox, because summarizing is a drafting task and chatboxes are built for drafting | G8: Either one, provided client names are removed first | H8: An automation, because the task is repeatable and can be routed through approved systems | I8: Either one, provided an attorney reviews the output before it is filed | J8: 2 | K8: =IF(OR($J8="",NOT(ISNUMBER($J8)),$J8<0,$J8>3,COUNTA($F8:$I8)<4),"",INDEX($F8:$I8,$J8+1)) | L8: Lesson 1 describes automations as suited to repetitive or complex workflows, and Lesson 4 names summarizing attorney notes as something a vetted automation can safely handle. Summarizing genuinely is a drafting-style task and chatboxes genuinely are built for drafting, which is what makes the chatbox answer tempting, but the deciding factor is the route the data takes rather than the shape of the task. Removing names is not sufficient under Lesson 2, and attorney review is required either way without making an unapproved route acceptable. | M8: Ready for Katy | N8: Drafted from course text. Distractors are each true about something and wrong only in what they conclude. | O8: Lesson 1: Types of AI Tools in Legal Practice
A9: L1-08 | B9: 1 | C9: Introduction to AI in Legal Practice | D9: L1:speaking-up | E9: A staff member notices a colleague using an AI tool in a way that may be inconsistent with firm policy, but is not certain the policy applies. Under the course's treatment of shared responsibility, the appropriate response is to: | F9: Say nothing, since raising an uncertain concern could unfairly implicate a colleague | G9: Raise the question, because flagging a possible risk does not require being certain it is one | H9: Wait to see whether it happens again, so the concern is better supported before raising it | I9: Handle it privately with the colleague and avoid involving a supervisor | J9: 1 | K9: =IF(OR($J9="",NOT(ISNUMBER($J9)),$J9<0,$J9>3,COUNTA($F9:$I9)<4),"",INDEX($F9:$I9,$J9+1)) | L9: Lesson 1 states that every member of the firm shares responsibility, that anyone unsure about a process should speak up, and that open communication prevents mistakes before they happen. Fairness to a colleague is a real consideration and a repeated pattern really is more persuasive evidence. Speaking to the colleague directly is in fact what Lesson 4 recommends for an unapproved workflow, but the course pairs that with checking policy or the supervising attorney rather than keeping it private, and waiting for a second occurrence leaves the first uncorrected. | M9: Ready for Katy | N9: Drafted from course text. Distractors are each true about something and wrong only in what they conclude. | O9: Lesson 1: Roles and Responsibilities / Lesson 4: What Should You Do?
A10: L1-09 | B10: 1 | C10: Introduction to AI in Legal Practice | D10: L1:consequences | E10: The course notes that AI compliance failures can harm clients, damage the firm's reputation, and lead to ethical violations. Which statement about those consequences is accurate? | F10: They arise only once the AI output is filed with a court | G10: They attach to the supervising attorney but not to non-attorney staff | H10: They are substantially mitigated when the staff member acted in good faith | I10: They can arise from a single unreviewed output, whether or not it is ever filed | J10: 3 | K10: =IF(OR($J10="",NOT(ISNUMBER($J10)),$J10<0,$J10>3,COUNTA($F10:$I10)<4),"",INDEX($F10:$I10,$J10+1)) | L10: Lesson 1's own example is a client harmed after AI-generated content went out with bogus citations and incoherent content, which does not require a filing. Filings are indeed where sanctions are most visible, formal bar discipline does run to licensed attorneys, and good faith does bear on how a matter is ultimately treated. But the course locates the harm at the point the work reaches the client, makes compliance a shared responsibility, and states in Lesson 3 that unintentional mistakes do not absolve anyone of responsibility. | M10: Ready for Katy | N10: Drafted from course text. Distractors are each true about something and wrong only in what they conclude. | O10: Lesson 1: Knowledge Checkpoint / Lesson 3: verification knowledge check
A11: L1-10 | B11: 1 | C11: Introduction to AI in Legal Practice | D11: L1:pillars-independent | E11: The course insists confidentiality and accuracy are very different concerns requiring separate attention. What follows from treating them separately? | F11: A workflow that fully protects confidentiality still needs its own verification step | G11: A verified output can be shared through any tool, since accuracy was the risk being managed | H11: Confidentiality governs client data while accuracy governs court filings | I11: Addressing one generally addresses the other, since both stem from unsupervised use | J11: 0 | K11: =IF(OR($J11="",NOT(ISNUMBER($J11)),$J11<0,$J11>3,COUNTA($F11:$I11)<4),"",INDEX($F11:$I11,$J11+1)) | L11: Lesson 1 separates the two pillars precisely because a fix for one is not a fix for the other. A firm-approved automation protects the data route but says nothing about whether the output is factually right, which is why Lesson 3 treats verification as non-negotiable even inside approved workflows. Unsupervised use genuinely does feed both, and filings genuinely are where accuracy failures cost the most, but neither observation collapses the two concerns into one. | M11: Ready for Katy | N11: Drafted from course text. Distractors are each true about something and wrong only in what they conclude. | O11: Lesson 1: The Two Pillars of AI Compliance
A12: L2-01 | B12: 2 | C12: Protecting Client Confidentiality with AI Tools | D12: L2:vendor-assessment | E12: Before allowing staff to use an AI tool that processes client information, the supervising attorney should: | F12: Review only the tool's marketing page, since vendors are required to disclose material security limitations there | G12: Require staff to sign a personal liability waiver, so responsibility for any disclosure sits with the individual user | H12: Notify the state bar and await written guidance before any staff member uses the tool on client matters | I12: Evaluate the tool's data retention practices, confidentiality protections, and terms of service | J12: 3 | K12: =IF(OR($J12="",NOT(ISNUMBER($J12)),$J12<0,$J12>3,COUNTA($F12:$I12)<4),"",INDEX($F12:$I12,$J12+1)) | L12: Client data is subject to confidentiality obligations under Rule 1.6. An attorney must assess whether an AI vendor's data handling practices are compatible with those obligations before allowing staff use. | M12: Ready for Katy | N12: DISTRACTORS LENGTHENED 08-18 so answer length stops signalling the key. Correct answer untouched. Existing seed question. Tagged PLACEHOLDER in section_tag only: the text itself is real. Review for legal accuracy, then retag. | O12: Lesson 2: Firm Policies and Best Practices
A13: L2-02 | B13: 2 | C13: Protecting Client Confidentiality with AI Tools | D13: L2:identifiability | E13: A staff member removes the client's name, then enters these facts into a consumer chatbot: entered the country in 1998, six U.S. citizen children, a child with a rare genetic disorder treated at a named hospital, a prior removal order, and a recent workplace-raid arrest. Has confidentiality been protected? | F13: No, because the combination of details can reasonably identify the client | G13: No, but only because the hospital was named | H13: Yes, because no name, address, or file number was entered | I13: Yes, because each fact on its own is too general to identify anyone | J13: 0 | K13: =IF(OR($J13="",NOT(ISNUMBER($J13)),$J13<0,$J13>3,COUNTA($F13:$I13)<4),"",INDEX($F13:$I13,$J13+1)) | L13: This is Lesson 2's central scenario. Confidentiality extends to any information that could reasonably identify a client even when the name is never mentioned, and the lesson's point is that several unique details together are enough for someone to recognize the client, especially in a smaller community or an unusual case. Removing direct identifiers is a real step, any single fact here really is fairly general, and the named hospital really is especially identifying. None of those is the reason. The accumulation is. | M13: Ready for Katy | N13: Overlaps the in-course true/false on removing a name. Decide whether the exam should mirror that or avoid it. | O13: Lesson 2: Scenario: The Verified Hallucination / Sort Information
... A51: L5-10 | B51: 5 | C51: Applying Ethical Rules and Firm Policy to Everyday AI Use | D51: L5:escalation-target | E51: Lesson 5 gives a sequence for handling a new AI tool. After recognizing the tool and checking whether the firm has approved it, what happens when the question involves vendor evaluation or system security? | F51: Proceed within the boundaries of the staff member's role | G51: Escalate to an attorney or IT specialist for review | H51: Pause until the tool appears on the firm's approved list | I51: Request the vendor's security documentation and assess it | J51: 1 | K51: =IF(OR($J51="",NOT(ISNUMBER($J51)),$J51<0,$J51>3,COUNTA($F51:$I51)<4),"",INDEX($F51:$I51,$J51+1)) | L51: Lesson 5's sequence routes vendor evaluation and system security questions to an attorney or IT specialist for a thorough review, consistent with Lesson 4's statement that staff are not expected to determine technical compliance. Proceeding within boundaries is right once a tool is approved, waiting for the approved list is safe, and someone really does need to request the vendor's documentation. That assessment is the escalation target's work rather than the staff member's. | M51: Ready for Katy | N51: Drafted from course text. Distractors are each true about something and wrong only in what they conclude. | O51: Lesson 5: Recognize a New Tool or Workflow: Escalate for Review

Sheet Coverage
A1: Coverage and pool health
A2: Yellow cells are yours to change. Everything else is calculated.
A4: Lesson | B4: Title | C4: Served per attempt | D4: Target pool | E4: Written | F4: Approved | G4: Gap to target | H4: Expected repeats on a retake
A5: 1 | B5: Introduction to AI in Legal Practice | C5: 1 | D5: 8 | E5: =SUMPRODUCT(('Question Bank'!$B$2:$B$51=$A5)*('Question Bank'!$E$2:$E$51<>"")) | F5: =SUMPRODUCT(('Question Bank'!$B$2:$B$51=$A5)*('Question Bank'!$M$2:$M$51="Approved")) | G5: =MAX(0,$D5-$E5) | H5: =IF($F5=0,"",ROUND($C5^2/$F5,2))
A6: 2 | B6: Protecting Client Confidentiality with AI Tools | C6: 2 | D6: 8 | E6: =SUMPRODUCT(('Question Bank'!$B$2:$B$51=$A6)*('Question Bank'!$E$2:$E$51<>"")) | F6: =SUMPRODUCT(('Question Bank'!$B$2:$B$51=$A6)*('Question Bank'!$M$2:$M$51="Approved")) | G6: =MAX(0,$D6-$E6) | H6: =IF($F6=0,"",ROUND($C6^2/$F6,2))
A7: 3 | B7: Ensuring Accuracy: Verification and Supervision of AI Outputs | C7: 2 | D7: 8 | E7: =SUMPRODUCT(('Question Bank'!$B$2:$B$51=$A7)*('Question Bank'!$E$2:$E$51<>"")) | F7: =SUMPRODUCT(('Question Bank'!$B$2:$B$51=$A7)*('Question Bank'!$M$2:$M$51="Approved")) | G7: =MAX(0,$D7-$E7) | H7: =IF($F7=0,"",ROUND($C7^2/$F7,2))
A8: 4 | B8: Compliant AI Workflows: Automations vs. Chatbox Use | C8: 1 | D8: 8 | E8: =SUMPRODUCT(('Question Bank'!$B$2:$B$51=$A8)*('Question Bank'!$E$2:$E$51<>"")) | F8: =SUMPRODUCT(('Question Bank'!$B$2:$B$51=$A8)*('Question Bank'!$M$2:$M$51="Approved")) | G8: =MAX(0,$D8-$E8) | H8: =IF($F8=0,"",ROUND($C8^2/$F8,2))
A9: 5 | B9: Applying Ethical Rules and Firm Policy to Everyday AI Use | C9: 2 | D9: 8 | E9: =SUMPRODUCT(('Question Bank'!$B$2:$B$51=$A9)*('Question Bank'!$E$2:$E$51<>"")) | F9: =SUMPRODUCT(('Question Bank'!$B$2:$B$51=$A9)*('Question Bank'!$M$2:$M$51="Approved")) | G9: =MAX(0,$D9-$E9) | H9: =IF($F9=0,"",ROUND($C9^2/$F9,2))
B10: Total | C10: =SUM($C5:$C9) | D10: =SUM($D5:$D9) | E10: =SUM($E5:$E9) | F10: =SUM($F5:$F9) | G10: =SUM($G5:$G9) | H10: =IF($F10=0,"",ROUND(SUMPRODUCT(($F5:$F9>0)*($C5:$C9^2)/IF($F5:$F9=0,1,$F5:$F9)),2))
A12: How to read “Expected repeats on a retake”
A13: If a candidate fails and immediately retakes, this is how many of the 8 questions they can expect to have just seen.
A14: It is the approved pool that counts, not the written pool: only approved questions ship.
A16: Whole-exam guide, assuming an even pool across all five lessons:
A17: 6 per lesson (30 total) >> 2.33 of 8 repeat (29%) ... thin
A18: 8 per lesson (40 total) >> 1.75 of 8 repeat (22%) ... the knee of the curve
A19: 10 per lesson (50 total) >> 1.40 of 8 repeat (18%) ... small gain over 8
A20: 12 per lesson (60 total) >> 1.17 of 8 repeat (15%) ... diminishing
A22: Lessons 2, 3 and 5 serve 2 questions each per attempt; lessons 1 and 4 serve 1.
A23: A lesson that serves 2 needs roughly double the pool of one that serves 1 to feel equally fresh.
A25: Blueprint source: LESSON_BLUEPRINT in lib/training/assessment.ts:52 (1/2/2/1/2). Changing it is a one-line edit.

Sheet How to use
A1: How to use this workbook
A3: Fill in | B3: Yellow cells. Grey cells are calculated: do not type in them.
A4: Where questions live | B4: The 'Question Bank' tab. Slots are pre-numbered 10 per lesson; leave unused ones as 'Not written'.
A6: THE ONE TRAP | B6: correct_index is ZERO-BASED. 0 = Answer A, 1 = B, 2 = C, 3 = D.
B7: The database stores the correct choice by POSITION, not by wording. If you reorder the answer
B8: choices later, you must update correct_index too, or the question silently grades the wrong answer.
B9: Column K re-renders the correct answer from the index so you can eyeball it. Always check K reads
B10: the way you intended before marking a question Approved.
A12: Status values | B12: Not written: an empty slot
B13: Draft: written by Max, not yet sent
B14: Ready for Katy: sent for legal review
B15: Approved: Katy signed off; only these ship
B16: Needs rework: Katy wants changes, see Reviewer notes
B17: Rejected: dropped, kept for the record
A19: Every question needs | B19: Four answer choices, exactly one unambiguously best, and a short explanation.
B20: The explanation is shown to the employee on the retake screen after a failed attempt.
A22: section_tag | B22: A durable label for coverage analysis, e.g. L4:api-scope. The existing 8 are tagged
B23: PLACEHOLDER:*: that prefix is in the tag only, not in the question text. Retag on approval.
A25: Maps to these DB columns | B25: quiz_questions.question_text, .answers (JSON array of 4 strings), .correct_index,
B26: .explanation, .section_tag, .lesson (smallint 1-5, added in migration 0025).
A28: Example row | B28: ID: L4-01 | Lesson: 4 | section_tag: L4:data-route
B29: Question text: Two staff are asked to extract names and case types from fifty case files. One
B30: pastes them into a consumer chatbot; the other uses a firm-approved automation. What makes one
B31: compliant and the other not?
B32: Answer A: The second task is faster
B33: Answer B: The route the client data takes, not the task being performed
B34: Answer C: The first staff member lacked authorization to see the files
B35: Answer D: Nothing, since both used AI
B36: correct_index: 1 (because B is correct, and B is position 1 counting from 0)
B37: Explanation: The same task can be compliant or non-compliant depending on the route the data takes.
B38: Grounded in: Lesson 4: Scenario: Chatbox vs. Automations
B39: (Illustration of the format only. Not a submitted question: write your own.)
A41: Source material | B41: Course text extracted per lesson to lesson1.txt … lesson5.txt in the session scratchpad.
B42: Existing 8 questions: supabase/migrations/0003_quiz_questions.sql
B43: Per-question review notes: .planning/QUESTION-POOL.md
A45: Built | B45: 2026-08-18. Tracks ix-questionpool.
A47: Current state | B47: 2026-08-18. All 50 slots carry text.
B48: 8 questions at 'Needs review' are the original seed questions, verbatim from the database.
B49: 42 questions at 'Draft' were drafted from the course text and have had no legal review.
B50: Revise in place and move the status along as you go. Nothing here has been written to the database.
...
